Workbook

Sheet Assumptions
A1: الرمز | B1: البند | C1: القيمة | D1: المصدر / ملاحظة
A2: VAT | B2: ضريبة القيمة المضافة | C2: 0.15 | D2: مقرر نظاماً (ليس من العقد) - الأسعار مفترضة شاملة الضريبة
A3: COM | B3: عمولة هنقرستيشن (توصيل/استلام) | C3: 0.21 | D3: عقد ص4 البند خامساً-أ
A4: PAY | B4: عمولة الدفع الإلكتروني | C4: 0.025 | D4: عقد ص4 البند خامساً-أ
A5: ESH | B5: نسبة الطلبات المدفوعة إلكترونياً | C5: 1 | D5: افتراض متحفظ: 100% (غير محدد في العقد)
A6: HPLUS | B6: إضافة HPlus لكل طلب (ريال) | C6: 4 | D6: عقد ص6
A7: FOOD | B7: تكلفة الطعام % من سعر البيع المباشر بدون ضريبة | C7: 0.32 | D7: افتراض - يجب استبداله بتكلفة الوصفات
A8: PKG | B8: تغليف لكل طلب (ريال) | C8: 2 | D8: افتراض - يجب استبداله
A9: PMAX | B9: سقف حصة المطعم من خصم الاستلام (ريال) | C9: 2.5 | D9: عقد ص5
A10: PDISC | B10: خصم العميل على الاستلام | C10: 0.2 | D10: عقد ص5 ("يبدأ من 20%" ويحق لهنقرستيشن تغييره)
A11: U30 | B11: تكلفة التوصيل لسلة أقل من 30 ريال | C11: 7 | D11: غير مذكورة بالعقد - افتراض (أقل شريحة)
A12: SUB | B12: الاشتراك الشهري (ريال) | C12: 200 | D12: عقد ص4: 200 من 01/10/2026 إلى 01/02/2027 (غامض: شهري أم إجمالي)
A13: PRN | B13: طابعة V2s مرة واحدة (ريال) | C13: 500 | D13: عقد ص4
B15: شرائح تكلفة التوصيل (حسب قيمة السلة شاملة الضريبة)
A16: من (ريال) | B16: تكلفة التوصيل (ريال)
A17: 30 | B17: 7
A18: 40 | B18: 8
A19: 50 | B19: 9
A20: 60 | B20: 11
A21: 80 | B21: 13

Sheet Items
A1: # | B1: الصنف | C1: القسم | D1: سعر المطعم الحالي (Excel عمود D) | E1: سعر هنقرستيشن المقترح (Excel عمود F) | F1: نسبة الزيادة | G1: ضريبة 15% المضمنة في السعر | H1: عمولة 21% | I1: رسوم الدفع 2.5% | J1: تكلفة التوصيل (شريحة - طلب منفرد) | K1: إجمالي خصومات المنصة | L1: الصافي للمطعم قبل التكلفة (بعد الضريبة) | M1: الصافي % من سعر المطعم | N1: الصافي % من سعر HS | O1: الصافي % من البيع المباشر (بدون ضريبة) | P1: صافي طلب HPlus | Q1: أقصى تكلفة طعام+تغليف قبل الخسارة | R1: تكلفة طعام+تغليف (افتراض) | S1: هامش المساهمة (CM) | T1: CM % من سعر HS بدون ضريبة | U1: التصنيف | V1: CM البيع المباشر | W1: الفرق عن البيع المباشر | X1: صافي طلب الاستلام (Pickup) | Y1: سعر المنيو المطبوع | Z1: سعر HS ÷ سعر المنيو - 1 | AA1: ملاحظة
A2: 1 | B2: نفر حنيد بيتنا | C2: اطباق الرئيسية | D2: 105 | E2: 126 | F2: =E2/D2-1 | G2: =E2*Assumptions!$C$2/(1+Assumptions!$C$2) | H2: =E2*Assumptions!$C$3 | I2: =E2*Assumptions!$C$4*Assumptions!$C$5 | J2: =IF(E2<30,Assumptions!$C$11,LOOKUP(E2,Assumptions!$A$17:$A$21,Assumptions!$B$17:$B$21)) | K2: =H2+I2+J2 | L2: =E2-G2-K2 | M2: =L2/D2 | N2: =L2/E2 | O2: =L2/(D2/(1+Assumptions!$C$2)) | P2: =L2-Assumptions!$C$6 | Q2: =L2 | R2: =Assumptions!$C$7*D2/(1+Assumptions!$C$2)+Assumptions!$C$8 | S2: =L2-R2 | T2: =S2/(E2/(1+Assumptions!$C$2)) | U2: =IF(T2<0.15,"RED",IF(T2<0.3,"YELLOW","GREEN")) | V2: =D2/(1+Assumptions!$C$2)-R2 | W2: =S2-V2 | X2: =E2-G2-E2*Assumptions!$C$3-E2*Assumptions!$C$4*Assumptions!$C$5-MIN(Assumptions!$C$9,Assumptions!$C$10*E2) | Y2: 80 | Z2: =IF(Y2="","",E2/Y2-1)
A3: 2 | B3: حنيذ جيزاني | D3: 100 | E3: 120 | F3: =E3/D3-1 | G3: =E3*Assumptions!$C$2/(1+Assumptions!$C$2) | H3: =E3*Assumptions!$C$3 | I3: =E3*Assumptions!$C$4*Assumptions!$C$5 | J3: =IF(E3<30,Assumptions!$C$11,LOOKUP(E3,Assumptions!$A$17:$A$21,Assumptions!$B$17:$B$21)) | K3: =H3+I3+J3 | L3: =E3-G3-K3 | M3: =L3/D3 | N3: =L3/E3 | O3: =L3/(D3/(1+Assumptions!$C$2)) | P3: =L3-Assumptions!$C$6 | Q3: =L3 | R3: =Assumptions!$C$7*D3/(1+Assumptions!$C$2)+Assumptions!$C$8 | S3: =L3-R3 | T3: =S3/(E3/(1+Assumptions!$C$2)) | U3: =IF(T3<0.15,"RED",IF(T3<0.3,"YELLOW","GREEN")) | V3: =D3/(1+Assumptions!$C$2)-R3 | W3: =S3-V3 | X3: =E3-G3-E3*Assumptions!$C$3-E3*Assumptions!$C$4*Assumptions!$C$5-MIN(Assumptions!$C$9,Assumptions!$C$10*E3) | Y3: 77 | Z3: =IF(Y3="","",E3/Y3-1)
A4: 3 | B4: كبسة لحم | D4: 98 | E4: 117.6 | F4: =E4/D4-1 | G4: =E4*Assumptions!$C$2/(1+Assumptions!$C$2) | H4: =E4*Assumptions!$C$3 | I4: =E4*Assumptions!$C$4*Assumptions!$C$5 | J4: =IF(E4<30,Assumptions!$C$11,LOOKUP(E4,Assumptions!$A$17:$A$21,Assumptions!$B$17:$B$21)) | K4: =H4+I4+J4 | L4: =E4-G4-K4 | M4: =L4/D4 | N4: =L4/E4 | O4: =L4/(D4/(1+Assumptions!$C$2)) | P4: =L4-Assumptions!$C$6 | Q4: =L4 | R4: =Assumptions!$C$7*D4/(1+Assumptions!$C$2)+Assumptions!$C$8 | S4: =L4-R4 | T4: =S4/(E4/(1+Assumptions!$C$2)) | U4: =IF(T4<0.15,"RED",IF(T4<0.3,"YELLOW","GREEN")) | V4: =D4/(1+Assumptions!$C$2)-R4 | W4: =S4-V4 | X4: =E4-G4-E4*Assumptions!$C$3-E4*Assumptions!$C$4*Assumptions!$C$5-MIN(Assumptions!$C$9,Assumptions!$C$10*E4) | Y4: 75 | Z4: =IF(Y4="","",E4/Y4-1)
A5: 4 | B5: برمة لحم مع الرز | D5: 48 | E5: 57.6 | F5: =E5/D5-1 | G5: =E5*Assumptions!$C$2/(1+Assumptions!$C$2) | H5: =E5*Assumptions!$C$3 | I5: =E5*Assumptions!$C$4*Assumptions!$C$5 | J5: =IF(E5<30,Assumptions!$C$11,LOOKUP(E5,Assumptions!$A$17:$A$21,Assumptions!$B$17:$B$21)) | K5: =H5+I5+J5 | L5: =E5-G5-K5 | M5: =L5/D5 | N5: =L5/E5 | O5: =L5/(D5/(1+Assumptions!$C$2)) | P5: =L5-Assumptions!$C$6 | Q5: =L5 | R5: =Assumptions!$C$7*D5/(1+Assumptions!$C$2)+Assumptions!$C$8 | S5: =L5-R5 | T5: =S5/(E5/(1+Assumptions!$C$2)) | U5: =IF(T5<0.15,"RED",IF(T5<0.3,"YELLOW","GREEN")) | V5: =D5/(1+Assumptions!$C$2)-R5 | W5: =S5-V5 | X5: =E5-G5-E5*Assumptions!$C$3-E5*Assumptions!$C$4*Assumptions!$C$5-MIN(Assumptions!$C$9,Assumptions!$C$10*E5) | Y5: 36 | Z5: =IF(Y5="","",E5/Y5-1)
A6: 5 | B6: مغش لحم | D6: 59 | E6: 70.8 | F6: =E6/D6-1 | G6: =E6*Assumptions!$C$2/(1+Assumptions!$C$2) | H6: =E6*Assumptions!$C$3 | I6: =E6*Assumptions!$C$4*Assumptions!$C$5 | J6: =IF(E6<30,Assumptions!$C$11,LOOKUP(E6,Assumptions!$A$17:$A$21,Assumptions!$B$17:$B$21)) | K6: =H6+I6+J6 | L6: =E6-G6-K6 | M6: =L6/D6 | N6: =L6/E6 | O6: =L6/(D6/(1+Assumptions!$C$2)) | P6: =L6-Assumptions!$C$6 | Q6: =L6 | R6: =Assumptions!$C$7*D6/(1+Assumptions!$C$2)+Assumptions!$C$8 | S6: =L6-R6 | T6: =S6/(E6/(1+Assumptions!$C$2)) | U6: =IF(T6<0.15,"RED",IF(T6<0.3,"YELLOW","GREEN")) | V6: =D6/(1+Assumptions!$C$2)-R6 | W6: =S6-V6 | X6: =E6-G6-E6*Assumptions!$C$3-E6*Assumptions!$C$4*Assumptions!$C$5-MIN(Assumptions!$C$9,Assumptions!$C$10*E6) | Y6: 45 | Z6: =IF(Y6="","",E6/Y6-1)
A7: 6 | B7: ربع شواية مع الرز | D7: 19 | E7: 22.8 | F7: =E7/D7-1 | G7: =E7*Assumptions!$C$2/(1+Assumptions!$C$2) | H7: =E7*Assumptions!$C$3 | I7: =E7*Assumptions!$C$4*Assumptions!$C$5 | J7: =IF(E7<30,Assumptions!$C$11,LOOKUP(E7,Assumptions!$A$17:$A$21,Assumptions!$B$17:$B$21)) | K7: =H7+I7+J7 | L7: =E7-G7-K7 | M7: =L7/D7 | N7: =L7/E7 | O7: =L7/(D7/(1+Assumptions!$C$2)) | P7: =L7-Assumptions!$C$6 | Q7: =L7 | R7: =Assumptions!$C$7*D7/(1+Assumptions!$C$2)+Assumptions!$C$8 | S7: =L7-R7 | T7: =S7/(E7/(1+Assumptions!$C$2)) | U7: =IF(T7<0.15,"RED",IF(T7<0.3,"YELLOW","GREEN")) | V7: =D7/(1+Assumptions!$C$2)-R7 | W7: =S7-V7 | X7: =E7-G7-E7*Assumptions!$C$3-E7*Assumptions!$C$4*Assumptions!$C$5-MIN(Assumptions!$C$9,Assumptions!$C$10*E7) | Y7: 14 | Z7: =IF(Y7="","",E7/Y7-1)
A8: 7 | B8: نص شواية مع الرز | D8: 27 | E8: 32.4 | F8: =E8/D8-1 | G8: =E8*Assumptions!$C$2/(1+Assumptions!$C$2) | H8: =E8*Assumptions!$C$3 | I8: =E8*Assumptions!$C$4*Assumptions!$C$5 | J8: =IF(E8<30,Assumptions!$C$11,LOOKUP(E8,Assumptions!$A$17:$A$21,Assumptions!$B$17:$B$21)) | K8: =H8+I8+J8 | L8: =E8-G8-K8 | M8: =L8/D8 | N8: =L8/E8 | O8: =L8/(D8/(1+Assumptions!$C$2)) | P8: =L8-Assumptions!$C$6 | Q8: =L8 | R8: =Assumptions!$C$7*D8/(1+Assumptions!$C$2)+Assumptions!$C$8 | S8: =L8-R8 | T8: =S8/(E8/(1+Assumptions!$C$2)) | U8: =IF(T8<0.15,"RED",IF(T8<0.3,"YELLOW","GREEN")) | V8: =D8/(1+Assumptions!$C$2)-R8 | W8: =S8-V8 | X8: =E8-G8-E8*Assumptions!$C$3-E8*Assumptions!$C$4*Assumptions!$C$5-MIN(Assumptions!$C$9,Assumptions!$C$10*E8) | Y8: 21 | Z8: =IF(Y8="","",E8/Y8-1)
A9: 8 | B9: حبه شوايه مع الرز | D9: 55 | E9: 66 | F9: =E9/D9-1 | G9: =E9*Assumptions!$C$2/(1+Assumptions!$C$2) | H9: =E9*Assumptions!$C$3 | I9: =E9*Assumptions!$C$4*Assumptions!$C$5 | J9: =IF(E9<30,Assumptions!$C$11,LOOKUP(E9,Assumptions!$A$17:$A$21,Assumptions!$B$17:$B$21)) | K9: =H9+I9+J9 | L9: =E9-G9-K9 | M9: =L9/D9 | N9: =L9/E9 | O9: =L9/(D9/(1+Assumptions!$C$2)) | P9: =L9-Assumptions!$C$6 | Q9: =L9 | R9: =Assumptions!$C$7*D9/(1+Assumptions!$C$2)+Assumptions!$C$8 | S9: =L9-R9 | T9: =S9/(E9/(1+Assumptions!$C$2)) | U9: =IF(T9<0.15,"RED",IF(T9<0.3,"YELLOW","GREEN")) | V9: =D9/(1+Assumptions!$C$2)-R9 | W9: =S9-V9 | X9: =E9-G9-E9*Assumptions!$C$3-E9*Assumptions!$C$4*Assumptions!$C$5-MIN(Assumptions!$C$9,Assumptions!$C$10*E9) | Y9: 42 | Z9: =IF(Y9="","",E9/Y9-1)
A10: 9 | B10: حبه مقلوبه مع الرز | D10: 55 | E10: 66 | F10: =E10/D10-1 | G10: =E10*Assumptions!$C$2/(1+Assumptions!$C$2) | H10: =E10*Assumptions!$C$3 | I10: =E10*Assumptions!$C$4*Assumptions!$C$5 | J10: =IF(E10<30,Assumptions!$C$11,LOOKUP(E10,Assumptions!$A$17:$A$21,Assumptions!$B$17:$B$21)) | K10: =H10+I10+J10 | L10: =E10-G10-K10 | M10: =L10/D10 | N10: =L10/E10 | O10: =L10/(D10/(1+Assumptions!$C$2)) | P10: =L10-Assumptions!$C$6 | Q10: =L10 | R10: =Assumptions!$C$7*D10/(1+Assumptions!$C$2)+Assumptions!$C$8 | S10: =L10-R10 | T10: =S10/(E10/(1+Assumptions!$C$2)) | U10: =IF(T10<0.15,"RED",IF(T10<0.3,"YELLOW","GREEN")) | V10: =D10/(1+Assumptions!$C$2)-R10 | W10: =S10-V10 | X10: =E10-G10-E10*Assumptions!$C$3-E10*Assumptions!$C$4*Assumptions!$C$5-MIN(Assumptions!$C$9,Assumptions!$C$10*E10) | Z10: =IF(Y10="","",E10/Y10-1) | AA10: الصنف غير موجود في المنيو المطبوع
A11: 10 | B11: نص مضغوط | D11: 27 | E11: 32.4 | F11: =E11/D11-1 | G11: =E11*Assumptions!$C$2/(1+Assumptions!$C$2) | H11: =E11*Assumptions!$C$3 | I11: =E11*Assumptions!$C$4*Assumptions!$C$5 | J11: =IF(E11<30,Assumptions!$C$11,LOOKUP(E11,Assumptions!$A$17:$A$21,Assumptions!$B$17:$B$21)) | K11: =H11+I11+J11 | L11: =E11-G11-K11 | M11: =L11/D11 | N11: =L11/E11 | O11: =L11/(D11/(1+Assumptions!$C$2)) | P11: =L11-Assumptions!$C$6 | Q11: =L11 | R11: =Assumptions!$C$7*D11/(1+Assumptions!$C$2)+Assumptions!$C$8 | S11: =L11-R11 | T11: =S11/(E11/(1+Assumptions!$C$2)) | U11: =IF(T11<0.15,"RED",IF(T11<0.3,"YELLOW","GREEN")) | V11: =D11/(1+Assumptions!$C$2)-R11 | W11: =S11-V11 | X11: =E11-G11-E11*Assumptions!$C$3-E11*Assumptions!$C$4*Assumptions!$C$5-MIN(Assumptions!$C$9,Assumptions!$C$10*E11) | Y11: 21 | Z11: =IF(Y11="","",E11/Y11-1)
A12: 11 | B12: نص ميفى مع الرز | D12: 27 | E12: 32.4 | F12: =E12/D12-1 | G12: =E12*Assumptions!$C$2/(1+Assumptions!$C$2) | H12: =E12*Assumptions!$C$3 | I12: =E12*Assumptions!$C$4*Assumptions!$C$5 | J12: =IF(E12<30,Assumptions!$C$11,LOOKUP(E12,Assumptions!$A$17:$A$21,Assumptions!$B$17:$B$21)) | K12: =H12+I12+J12 | L12: =E12-G12-K12 | M12: =L12/D12 | N12: =L12/E12 | O12: =L12/(D12/(1+Assumptions!$C$2)) | P12: =L12-Assumptions!$C$6 | Q12: =L12 | R12: =Assumptions!$C$7*D12/(1+Assumptions!$C$2)+Assumptions!$C$8 | S12: =L12-R12 | T12: =S12/(E12/(1+Assumptions!$C$2)) | U12: =IF(T12<0.15,"RED",IF(T12<0.3,"YELLOW","GREEN")) | V12: =D12/(1+Assumptions!$C$2)-R12 | W12: =S12-V12 | X12: =E12-G12-E12*Assumptions!$C$3-E12*Assumptions!$C$4*Assumptions!$C$5-MIN(Assumptions!$C$9,Assumptions!$C$10*E12) | Y12: 21 | Z12: =IF(Y12="","",E12/Y12-1)
A13: 12 | B13: نص شواية سادة | D13: 20 | E13: 24 | F13: =E13/D13-1 | G13: =E13*Assumptions!$C$2/(1+Assumptions!$C$2) | H13: =E13*Assumptions!$C$3 | I13: =E13*Assumptions!$C$4*Assumptions!$C$5 | J13: =IF(E13<30,Assumptions!$C$11,LOOKUP(E13,Assumptions!$A$17:$A$21,Assumptions!$B$17:$B$21)) | K13: =H13+I13+J13 | L13: =E13-G13-K13 | M13: =L13/D13 | N13: =L13/E13 | O13: =L13/(D13/(1+Assumptions!$C$2)) | P13: =L13-Assumptions!$C$6 | Q13: =L13 | R13: =Assumptions!$C$7*D13/(1+Assumptions!$C$2)+Assumptions!$C$8 | S13: =L13-R13 | T13: =S13/(E13/(1+Assumptions!$C$2)) | U13: =IF(T13<0.15,"RED",IF(T13<0.3,"YELLOW","GREEN")) | V13: =D13/(1+Assumptions!$C$2)-R13 | W13: =S13-V13 | X13: =E13-G13-E13*Assumptions!$C$3-E13*Assumptions!$C$4*Assumptions!$C$5-MIN(Assumptions!$C$9,Assumptions!$C$10*E13) | Y13: 15 | Z13: =IF(Y13="","",E13/Y13-1)
A14: 13 | B14: نص ميفى سادة | D14: 20 | E14: 24 | F14: =E14/D14-1 | G14: =E14*Assumptions!$C$2/(1+Assumptions!$C$2) | H14: =E14*Assumptions!$C$3 | I14: =E14*Assumptions!$C$4*Assumptions!$C$5 | J14: =IF(E14<30,Assumptions!$C$11,LOOKUP(E14,Assumptions!$A$17:$A$21,Assumptions!$B$17:$B$21)) | K14: =H14+I14+J14 | L14: =E14-G14-K14 | M14: =L14/D14 | N14: =L14/E14 | O14: =L14/(D14/(1+Assumptions!$C$2)) | P14: =L14-Assumptions!$C$6 | Q14: =L14 | R14: =Assumptions!$C$7*D14/(1+Assumptions!$C$2)+Assumptions!$C$8 | S14: =L14-R14 | T14: =S14/(E14/(1+Assumptions!$C$2)) | U14: =IF(T14<0.15,"RED",IF(T14<0.3,"YELLOW","GREEN")) | V14: =D14/(1+Assumptions!$C$2)-R14 | W14: =S14-V14 | X14: =E14-G14-E14*Assumptions!$C$3-E14*Assumptions!$C$4*Assumptions!$C$5-MIN(Assumptions!$C$9,Assumptions!$C$10*E14) | Y14: 15 | Z14: =IF(Y14="","",E14/Y14-1)
A15: 14 | B15: حبة ميفى | D15: 55 | E15: 66 | F15: =E15/D15-1 | G15: =E15*Assumptions!$C$2/(1+Assumptions!$C$2) | H15: =E15*Assumptions!$C$3 | I15: =E15*Assumptions!$C$4*Assumptions!$C$5 | J15: =IF(E15<30,Assumptions!$C$11,LOOKUP(E15,Assumptions!$A$17:$A$21,Assumptions!$B$17:$B$21)) | K15: =H15+I15+J15 | L15: =E15-G15-K15 | M15: =L15/D15 | N15: =L15/E15 | O15: =L15/(D15/(1+Assumptions!$C$2)) | P15: =L15-Assumptions!$C$6 | Q15: =L15 | R15: =Assumptions!$C$7*D15/(1+Assumptions!$C$2)+Assumptions!$C$8 | S15: =L15-R15 | T15: =S15/(E15/(1+Assumptions!$C$2)) | U15: =IF(T15<0.15,"RED",IF(T15<0.3,"YELLOW","GREEN")) | V15: =D15/(1+Assumptions!$C$2)-R15 | W15: =S15-V15 | X15: =E15-G15-E15*Assumptions!$C$3-E15*Assumptions!$C$4*Assumptions!$C$5-MIN(Assumptions!$C$9,Assumptions!$C$10*E15) | Y15: 42 | Z15: =IF(Y15="","",E15/Y15-1)
A16: 15 | B16: حبة مضغوط | D16: 55 | E16: 66 | F16: =E16/D16-1 | G16: =E16*Assumptions!$C$2/(1+Assumptions!$C$2) | H16: =E16*Assumptions!$C$3 | I16: =E16*Assumptions!$C$4*Assumptions!$C$5 | J16: =IF(E16<30,Assumptions!$C$11,LOOKUP(E16,Assumptions!$A$17:$A$21,Assumptions!$B$17:$B$21)) | K16: =H16+I16+J16 | L16: =E16-G16-K16 | M16: =L16/D16 | N16: =L16/E16 | O16: =L16/(D16/(1+Assumptions!$C$2)) | P16: =L16-Assumptions!$C$6 | Q16: =L16 | R16: =Assumptions!$C$7*D16/(1+Assumptions!$C$2)+Assumptions!$C$8 | S16: =L16-R16 | T16: =S16/(E16/(1+Assumptions!$C$2)) | U16: =IF(T16<0.15,"RED",IF(T16<0.3,"YELLOW","GREEN")) | V16: =D16/(1+Assumptions!$C$2)-R16 | W16: =S16-V16 | X16: =E16-G16-E16*Assumptions!$C$3-E16*Assumptions!$C$4*Assumptions!$C$5-MIN(Assumptions!$C$9,Assumptions!$C$10*E16) | Y16: 42 | Z16: =IF(Y16="","",E16/Y16-1)
A17: 16 | B17: نص مقلوبه | D17: 27 | E17: 32.4 | F17: =E17/D17-1 | G17: =E17*Assumptions!$C$2/(1+Assumptions!$C$2) | H17: =E17*Assumptions!$C$3 | I17: =E17*Assumptions!$C$4*Assumptions!$C$5 | J17: =IF(E17<30,Assumptions!$C$11,LOOKUP(E17,Assumptions!$A$17:$A$21,Assumptions!$B$17:$B$21)) | K17: =H17+I17+J17 | L17: =E17-G17-K17 | M17: =L17/D17 | N17: =L17/E17 | O17: =L17/(D17/(1+Assumptions!$C$2)) | P17: =L17-Assumptions!$C$6 | Q17: =L17 | R17: =Assumptions!$C$7*D17/(1+Assumptions!$C$2)+Assumptions!$C$8 | S17: =L17-R17 | T17: =S17/(E17/(1+Assumptions!$C$2)) | U17: =IF(T17<0.15,"RED",IF(T17<0.3,"YELLOW","GREEN")) | V17: =D17/(1+Assumptions!$C$2)-R17 | W17: =S17-V17 | X17: =E17-G17-E17*Assumptions!$C$3-E17*Assumptions!$C$4*Assumptions!$C$5-MIN(Assumptions!$C$9,Assumptions!$C$10*E17) | Y17: 21 | Z17: =IF(Y17="","",E17/Y17-1)
A18: 17 | B18: لحوح مكشن | D18: 25 | E18: 30 | F18: =E18/D18-1 | G18: =E18*Assumptions!$C$2/(1+Assumptions!$C$2) | H18: =E18*Assumptions!$C$3 | I18: =E18*Assumptions!$C$4*Assumptions!$C$5 | J18: =IF(E18<30,Assumptions!$C$11,LOOKUP(E18,Assumptions!$A$17:$A$21,Assumptions!$B$17:$B$21)) | K18: =H18+I18+J18 | L18: =E18-G18-K18 | M18: =L18/D18 | N18: =L18/E18 | O18: =L18/(D18/(1+Assumptions!$C$2)) | P18: =L18-Assumptions!$C$6 | Q18: =L18 | R18: =Assumptions!$C$7*D18/(1+Assumptions!$C$2)+Assumptions!$C$8 | S18: =L18-R18 | T18: =S18/(E18/(1+Assumptions!$C$2)) | U18: =IF(T18<0.15,"RED",IF(T18<0.3,"YELLOW","GREEN")) | V18: =D18/(1+Assumptions!$C$2)-R18 | W18: =S18-V18 | X18: =E18-G18-E18*Assumptions!$C$3-E18*Assumptions!$C$4*Assumptions!$C$5-MIN(Assumptions!$C$9,Assumptions!$C$10*E18) | Y18: 18 | Z18: =IF(Y18="","",E18/Y18-1)
A19: 18 | B19: مرقوق بيتنا لحم | C19: المروق | D19: 65 | E19: 78 | F19: =E19/D19-1 | G19: =E19*Assumptions!$C$2/(1+Assumptions!$C$2) | H19: =E19*Assumptions!$C$3 | I19: =E19*Assumptions!$C$4*Assumptions!$C$5 | J19: =IF(E19<30,Assumptions!$C$11,LOOKUP(E19,Assumptions!$A$17:$A$21,Assumptions!$B$17:$B$21)) | K19: =H19+I19+J19 | L19: =E19-G19-K19 | M19: =L19/D19 | N19: =L19/E19 | O19: =L19/(D19/(1+Assumptions!$C$2)) | P19: =L19-Assumptions!$C$6 | Q19: =L19 | R19: =Assumptions!$C$7*D19/(1+Assumptions!$C$2)+Assumptions!$C$8 | S19: =L19-R19 | T19: =S19/(E19/(1+Assumptions!$C$2)) | U19: =IF(T19<0.15,"RED",IF(T19<0.3,"YELLOW","GREEN")) | V19: =D19/(1+Assumptions!$C$2)-R19 | W19: =S19-V19 | X19: =E19-G19-E19*Assumptions!$C$3-E19*Assumptions!$C$4*Assumptions!$C$5-MIN(Assumptions!$C$9,Assumptions!$C$10*E19) | Y19: 50 | Z19: =IF(Y19="","",E19/Y19-1)
A20: 19 | B20: مرقوق بيتنا | D20: 35 | E20: 42 | F20: =E20/D20-1 | G20: =E20*Assumptions!$C$2/(1+Assumptions!$C$2) | H20: =E20*Assumptions!$C$3 | I20: =E20*Assumptions!$C$4*Assumptions!$C$5 | J20: =IF(E20<30,Assumptions!$C$11,LOOKUP(E20,Assumptions!$A$17:$A$21,Assumptions!$B$17:$B$21)) | K20: =H20+I20+J20 | L20: =E20-G20-K20 | M20: =L20/D20 | N20: =L20/E20 | O20: =L20/(D20/(1+Assumptions!$C$2)) | P20: =L20-Assumptions!$C$6 | Q20: =L20 | R20: =Assumptions!$C$7*D20/(1+Assumptions!$C$2)+Assumptions!$C$8 | S20: =L20-R20 | T20: =S20/(E20/(1+Assumptions!$C$2)) | U20: =IF(T20<0.15,"RED",IF(T20<0.3,"YELLOW","GREEN")) | V20: =D20/(1+Assumptions!$C$2)-R20 | W20: =S20-V20 | X20: =E20-G20-E20*Assumptions!$C$3-E20*Assumptions!$C$4*Assumptions!$C$5-MIN(Assumptions!$C$9,Assumptions!$C$10*E20) | Y20: 27 | Z20: =IF(Y20="","",E20/Y20-1)
A21: 20 | B21: مرسه بلدي | D21: 33 | E21: 39.6 | F21: =E21/D21-1 | G21: =E21*Assumptions!$C$2/(1+Assumptions!$C$2) | H21: =E21*Assumptions!$C$3 | I21: =E21*Assumptions!$C$4*Assumptions!$C$5 | J21: =IF(E21<30,Assumptions!$C$11,LOOKUP(E21,Assumptions!$A$17:$A$21,Assumptions!$B$17:$B$21)) | K21: =H21+I21+J21 | L21: =E21-G21-K21 | M21: =L21/D21 | N21: =L21/E21 | O21: =L21/(D21/(1+Assumptions!$C$2)) | P21: =L21-Assumptions!$C$6 | Q21: =L21 | R21: =Assumptions!$C$7*D21/(1+Assumptions!$C$2)+Assumptions!$C$8 | S21: =L21-R21 | T21: =S21/(E21/(1+Assumptions!$C$2)) | U21: =IF(T21<0.15,"RED",IF(T21<0.3,"YELLOW","GREEN")) | V21: =D21/(1+Assumptions!$C$2)-R21 | W21: =S21-V21 | X21: =E21-G21-E21*Assumptions!$C$3-E21*Assumptions!$C$4*Assumptions!$C$5-MIN(Assumptions!$C$9,Assumptions!$C$10*E21) | Y21: 25 | Z21: =IF(Y21="","",E21/Y21-1)
A22: 21 | B22: مرسه عادي | D22: 13 | E22: 15.6 | F22: =E22/D22-1 | G22: =E22*Assumptions!$C$2/(1+Assumptions!$C$2) | H22: =E22*Assumptions!$C$3 | I22: =E22*Assumptions!$C$4*Assumptions!$C$5 | J22: =IF(E22<30,Assumptions!$C$11,LOOKUP(E22,Assumptions!$A$17:$A$21,Assumptions!$B$17:$B$21)) | K22: =H22+I22+J22 | L22: =E22-G22-K22 | M22: =L22/D22 | N22: =L22/E22 | O22: =L22/(D22/(1+Assumptions!$C$2)) | P22: =L22-Assumptions!$C$6 | Q22: =L22 | R22: =Assumptions!$C$7*D22/(1+Assumptions!$C$2)+Assumptions!$C$8 | S22: =L22-R22 | T22: =S22/(E22/(1+Assumptions!$C$2)) | U22: =IF(T22<0.15,"RED",IF(T22<0.3,"YELLOW","GREEN")) | V22: =D22/(1+Assumptions!$C$2)-R22 | W22: =S22-V22 | X22: =E22-G22-E22*Assumptions!$C$3-E22*Assumptions!$C$4*Assumptions!$C$5-MIN(Assumptions!$C$9,Assumptions!$C$10*E22) | Y22: 10 | Z22: =IF(Y22="","",E22/Y22-1)
A23: 22 | B23: مرسة دخن | C23: المرسه والفته | D23: 33 | E23: 39.6 | F23: =E23/D23-1 | G23: =E23*Assumptions!$C$2/(1+Assumptions!$C$2) | H23: =E23*Assumptions!$C$3 | I23: =E23*Assumptions!$C$4*Assumptions!$C$5 | J23: =IF(E23<30,Assumptions!$C$11,LOOKUP(E23,Assumptions!$A$17:$A$21,Assumptions!$B$17:$B$21)) | K23: =H23+I23+J23 | L23: =E23-G23-K23 | M23: =L23/D23 | N23: =L23/E23 | O23: =L23/(D23/(1+Assumptions!$C$2)) | P23: =L23-Assumptions!$C$6 | Q23: =L23 | R23: =Assumptions!$C$7*D23/(1+Assumptions!$C$2)+Assumptions!$C$8 | S23: =L23-R23 | T23: =S23/(E23/(1+Assumptions!$C$2)) | U23: =IF(T23<0.15,"RED",IF(T23<0.3,"YELLOW","GREEN")) | V23: =D23/(1+Assumptions!$C$2)-R23 | W23: =S23-V23 | X23: =E23-G23-E23*Assumptions!$C$3-E23*Assumptions!$C$4*Assumptions!$C$5-MIN(Assumptions!$C$9,Assumptions!$C$10*E23) | Z23: =IF(Y23="","",E23/Y23-1) | AA23: الصنف غير موجود في المنيو المطبوع
A24: 23 | B24: فتة حديدي | D24: 13 | E24: 15.6 | F24: =E24/D24-1 | G24: =E24*Assumptions!$C$2/(1+Assumptions!$C$2) | H24: =E24*Assumptions!$C$3 | I24: =E24*Assumptions!$C$4*Assumptions!$C$5 | J24: =IF(E24<30,Assumptions!$C$11,LOOKUP(E24,Assumptions!$A$17:$A$21,Assumptions!$B$17:$B$21)) | K24: =H24+I24+J24 | L24: =E24-G24-K24 | M24: =L24/D24 | N24: =L24/E24 | O24: =L24/(D24/(1+Assumptions!$C$2)) | P24: =L24-Assumptions!$C$6 | Q24: =L24 | R24: =Assumptions!$C$7*D24/(1+Assumptions!$C$2)+Assumptions!$C$8 | S24: =L24-R24 | T24: =S24/(E24/(1+Assumptions!$C$2)) | U24: =IF(T24<0.15,"RED",IF(T24<0.3,"YELLOW","GREEN")) | V24: =D24/(1+Assumptions!$C$2)-R24 | W24: =S24-V24 | X24: =E24-G24-E24*Assumptions!$C$3-E24*Assumptions!$C$4*Assumptions!$C$5-MIN(Assumptions!$C$9,Assumptions!$C$10*E24) | Y24: 10 | Z24: =IF(Y24="","",E24/Y24-1)
A25: 24 | B25: شفوت | D25: 20 | E25: 24 | F25: =E25/D25-1 | G25: =E25*Assumptions!$C$2/(1+Assumptions!$C$2) | H25: =E25*Assumptions!$C$3 | I25: =E25*Assumptions!$C$4*Assumptions!$C$5 | J25: =IF(E25<30,Assumptions!$C$11,LOOKUP(E25,Assumptions!$A$17:$A$21,Assumptions!$B$17:$B$21)) | K25: =H25+I25+J25 | L25: =E25-G25-K25 | M25: =L25/D25 | N25: =L25/E25 | O25: =L25/(D25/(1+Assumptions!$C$2)) | P25: =L25-Assumptions!$C$6 | Q25: =L25 | R25: =Assumptions!$C$7*D25/(1+Assumptions!$C$2)+Assumptions!$C$8 | S25: =L25-R25 | T25: =S25/(E25/(1+Assumptions!$C$2)) | U25: =IF(T25<0.15,"RED",IF(T25<0.3,"YELLOW","GREEN")) | V25: =D25/(1+Assumptions!$C$2)-R25 | W25: =S25-V25 | X25: =E25-G25-E25*Assumptions!$C$3-E25*Assumptions!$C$4*Assumptions!$C$5-MIN(Assumptions!$C$9,Assumptions!$C$10*E25) | Y25: 15 | Z25: =IF(Y25="","",E25/Y25-1)
A26: 25 | B26: ملوخية | D26: 10 | E26: 12 | F26: =E26/D26-1 | G26: =E26*Assumptions!$C$2/(1+Assumptions!$C$2) | H26: =E26*Assumptions!$C$3 | I26: =E26*Assumptions!$C$4*Assumptions!$C$5 | J26: =IF(E26<30,Assumptions!$C$11,LOOKUP(E26,Assumptions!$A$17:$A$21,Assumptions!$B$17:$B$21)) | K26: =H26+I26+J26 | L26: =E26-G26-K26 | M26: =L26/D26 | N26: =L26/E26 | O26: =L26/(D26/(1+Assumptions!$C$2)) | P26: =L26-Assumptions!$C$6 | Q26: =L26 | R26: =Assumptions!$C$7*D26/(1+Assumptions!$C$2)+Assumptions!$C$8 | S26: =L26-R26 | T26: =S26/(E26/(1+Assumptions!$C$2)) | U26: =IF(T26<0.15,"RED",IF(T26<0.3,"YELLOW","GREEN")) | V26: =D26/(1+Assumptions!$C$2)-R26 | W26: =S26-V26 | X26: =E26-G26-E26*Assumptions!$C$3-E26*Assumptions!$C$4*Assumptions!$C$5-MIN(Assumptions!$C$9,Assumptions!$C$10*E26) | Y26: 7 | Z26: =IF(Y26="","",E26/Y26-1)
A27: 26 | B27: مصقعه | C27: ايدامات وحسيه | D27: 10 | E27: 12 | F27: =E27/D27-1 | G27: =E27*Assumptions!$C$2/(1+Assumptions!$C$2) | H27: =E27*Assumptions!$C$3 | I27: =E27*Assumptions!$C$4*Assumptions!$C$5 | J27: =IF(E27<30,Assumptions!$C$11,LOOKUP(E27,Assumptions!$A$17:$A$21,Assumptions!$B$17:$B$21)) | K27: =H27+I27+J27 | L27: =E27-G27-K27 | M27: =L27/D27 | N27: =L27/E27 | O27: =L27/(D27/(1+Assumptions!$C$2)) | P27: =L27-Assumptions!$C$6 | Q27: =L27 | R27: =Assumptions!$C$7*D27/(1+Assumptions!$C$2)+Assumptions!$C$8 | S27: =L27-R27 | T27: =S27/(E27/(1+Assumptions!$C$2)) | U27: =IF(T27<0.15,"RED",IF(T27<0.3,"YELLOW","GREEN")) | V27: =D27/(1+Assumptions!$C$2)-R27 | W27: =S27-V27 | X27: =E27-G27-E27*Assumptions!$C$3-E27*Assumptions!$C$4*Assumptions!$C$5-MIN(Assumptions!$C$9,Assumptions!$C$10*E27) | Y27: 7 | Z27: =IF(Y27="","",E27/Y27-1)
A28: 27 | B28: مشكل ميفى | D28: 11 | E28: 13.2 | F28: =E28/D28-1 | G28: =E28*Assumptions!$C$2/(1+Assumptions!$C$2) | H28: =E28*Assumptions!$C$3 | I28: =E28*Assumptions!$C$4*Assumptions!$C$5 | J28: =IF(E28<30,Assumptions!$C$11,LOOKUP(E28,Assumptions!$A$17:$A$21,Assumptions!$B$17:$B$21)) | K28: =H28+I28+J28 | L28: =E28-G28-K28 | M28: =L28/D28 | N28: =L28/E28 | O28: =L28/(D28/(1+Assumptions!$C$2)) | P28: =L28-Assumptions!$C$6 | Q28: =L28 | R28: =Assumptions!$C$7*D28/(1+Assumptions!$C$2)+Assumptions!$C$8 | S28: =L28-R28 | T28: =S28/(E28/(1+Assumptions!$C$2)) | U28: =IF(T28<0.15,"RED",IF(T28<0.3,"YELLOW","GREEN")) | V28: =D28/(1+Assumptions!$C$2)-R28 | W28: =S28-V28 | X28: =E28-G28-E28*Assumptions!$C$3-E28*Assumptions!$C$4*Assumptions!$C$5-MIN(Assumptions!$C$9,Assumptions!$C$10*E28) | Y28: 8 | Z28: =IF(Y28="","",E28/Y28-1)
A29: 28 | B29: قوار | D29: 13 | E29: 15.6 | F29: =E29/D29-1 | G29: =E29*Assumptions!$C$2/(1+Assumptions!$C$2) | H29: =E29*Assumptions!$C$3 | I29: =E29*Assumptions!$C$4*Assumptions!$C$5 | J29: =IF(E29<30,Assumptions!$C$11,LOOKUP(E29,Assumptions!$A$17:$A$21,Assumptions!$B$17:$B$21)) | K29: =H29+I29+J29 | L29: =E29-G29-K29 | M29: =L29/D29 | N29: =L29/E29 | O29: =L29/(D29/(1+Assumptions!$C$2)) | P29: =L29-Assumptions!$C$6 | Q29: =L29 | R29: =Assumptions!$C$7*D29/(1+Assumptions!$C$2)+Assumptions!$C$8 | S29: =L29-R29 | T29: =S29/(E29/(1+Assumptions!$C$2)) | U29: =IF(T29<0.15,"RED",IF(T29<0.3,"YELLOW","GREEN")) | V29: =D29/(1+Assumptions!$C$2)-R29 | W29: =S29-V29 | X29: =E29-G29-E29*Assumptions!$C$3-E29*Assumptions!$C$4*Assumptions!$C$5-MIN(Assumptions!$C$9,Assumptions!$C$10*E29) | Y29: 10 | Z29: =IF(Y29="","",E29/Y29-1)
A30: 29 | B30: مكشن اندومي | D30: 22 | E30: 26.4 | F30: =E30/D30-1 | G30: =E30*Assumptions!$C$2/(1+Assumptions!$C$2) | H30: =E30*Assumptions!$C$3 | I30: =E30*Assumptions!$C$4*Assumptions!$C$5 | J30: =IF(E30<30,Assumptions!$C$11,LOOKUP(E30,Assumptions!$A$17:$A$21,Assumptions!$B$17:$B$21)) | K30: =H30+I30+J30 | L30: =E30-G30-K30 | M30: =L30/D30 | N30: =L30/E30 | O30: =L30/(D30/(1+Assumptions!$C$2)) | P30: =L30-Assumptions!$C$6 | Q30: =L30 | R30: =Assumptions!$C$7*D30/(1+Assumptions!$C$2)+Assumptions!$C$8 | S30: =L30-R30 | T30: =S30/(E30/(1+Assumptions!$C$2)) | U30: =IF(T30<0.15,"RED",IF(T30<0.3,"YELLOW","GREEN")) | V30: =D30/(1+Assumptions!$C$2)-R30 | W30: =S30-V30 | X30: =E30-G30-E30*Assumptions!$C$3-E30*Assumptions!$C$4*Assumptions!$C$5-MIN(Assumptions!$C$9,Assumptions!$C$10*E30) | Y30: 17 | Z30: =IF(Y30="","",E30/Y30-1)
A31: 30 | B31: رز | D31: 10 | E31: 12 | F31: =E31/D31-1 | G31: =E31*Assumptions!$C$2/(1+Assumptions!$C$2) | H31: =E31*Assumptions!$C$3 | I31: =E31*Assumptions!$C$4*Assumptions!$C$5 | J31: =IF(E31<30,Assumptions!$C$11,LOOKUP(E31,Assumptions!$A$17:$A$21,Assumptions!$B$17:$B$21)) | K31: =H31+I31+J31 | L31: =E31-G31-K31 | M31: =L31/D31 | N31: =L31/E31 | O31: =L31/(D31/(1+Assumptions!$C$2)) | P31: =L31-Assumptions!$C$6 | Q31: =L31 | R31: =Assumptions!$C$7*D31/(1+Assumptions!$C$2)+Assumptions!$C$8 | S31: =L31-R31 | T31: =S31/(E31/(1+Assumptions!$C$2)) | U31: =IF(T31<0.15,"RED",IF(T31<0.3,"YELLOW","GREEN")) | V31: =D31/(1+Assumptions!$C$2)-R31 | W31: =S31-V31 | X31: =E31-G31-E31*Assumptions!$C$3-E31*Assumptions!$C$4*Assumptions!$C$5-MIN(Assumptions!$C$9,Assumptions!$C$10*E31) | Y31: 8 | Z31: =IF(Y31="","",E31/Y31-1)
A32: 31 | B32: مكشن سمك | D32: 58 | E32: 69.6 | F32: =E32/D32-1 | G32: =E32*Assumptions!$C$2/(1+Assumptions!$C$2) | H32: =E32*Assumptions!$C$3 | I32: =E32*Assumptions!$C$4*Assumptions!$C$5 | J32: =IF(E32<30,Assumptions!$C$11,LOOKUP(E32,Assumptions!$A$17:$A$21,Assumptions!$B$17:$B$21)) | K32: =H32+I32+J32 | L32: =E32-G32-K32 | M32: =L32/D32 | N32: =L32/E32 | O32: =L32/(D32/(1+Assumptions!$C$2)) | P32: =L32-Assumptions!$C$6 | Q32: =L32 | R32: =Assumptions!$C$7*D32/(1+Assumptions!$C$2)+Assumptions!$C$8 | S32: =L32-R32 | T32: =S32/(E32/(1+Assumptions!$C$2)) | U32: =IF(T32<0.15,"RED",IF(T32<0.3,"YELLOW","GREEN")) | V32: =D32/(1+Assumptions!$C$2)-R32 | W32: =S32-V32 | X32: =E32-G32-E32*Assumptions!$C$3-E32*Assumptions!$C$4*Assumptions!$C$5-MIN(Assumptions!$C$9,Assumptions!$C$10*E32) | Y32: 45 | Z32: =IF(Y32="","",E32/Y32-1)
A33: 32 | B33: حسيه خمير | D33: 22 | E33: 26.4 | F33: =E33/D33-1 | G33: =E33*Assumptions!$C$2/(1+Assumptions!$C$2) | H33: =E33*Assumptions!$C$3 | I33: =E33*Assumptions!$C$4*Assumptions!$C$5 | J33: =IF(E33<30,Assumptions!$C$11,LOOKUP(E33,Assumptions!$A$17:$A$21,Assumptions!$B$17:$B$21)) | K33: =H33+I33+J33 | L33: =E33-G33-K33 | M33: =L33/D33 | N33: =L33/E33 | O33: =L33/(D33/(1+Assumptions!$C$2)) | P33: =L33-Assumptions!$C$6 | Q33: =L33 | R33: =Assumptions!$C$7*D33/(1+Assumptions!$C$2)+Assumptions!$C$8 | S33: =L33-R33 | T33: =S33/(E33/(1+Assumptions!$C$2)) | U33: =IF(T33<0.15,"RED",IF(T33<0.3,"YELLOW","GREEN")) | V33: =D33/(1+Assumptions!$C$2)-R33 | W33: =S33-V33 | X33: =E33-G33-E33*Assumptions!$C$3-E33*Assumptions!$C$4*Assumptions!$C$5-MIN(Assumptions!$C$9,Assumptions!$C$10*E33) | Y33: 17 | Z33: =IF(Y33="","",E33/Y33-1)
A34: 33 | B34: حسيه لحم خمير | D34: 54 | E34: 64.8 | F34: =E34/D34-1 | G34: =E34*Assumptions!$C$2/(1+Assumptions!$C$2) | H34: =E34*Assumptions!$C$3 | I34: =E34*Assumptions!$C$4*Assumptions!$C$5 | J34: =IF(E34<30,Assumptions!$C$11,LOOKUP(E34,Assumptions!$A$17:$A$21,Assumptions!$B$17:$B$21)) | K34: =H34+I34+J34 | L34: =E34-G34-K34 | M34: =L34/D34 | N34: =L34/E34 | O34: =L34/(D34/(1+Assumptions!$C$2)) | P34: =L34-Assumptions!$C$6 | Q34: =L34 | R34: =Assumptions!$C$7*D34/(1+Assumptions!$C$2)+Assumptions!$C$8 | S34: =L34-R34 | T34: =S34/(E34/(1+Assumptions!$C$2)) | U34: =IF(T34<0.15,"RED",IF(T34<0.3,"YELLOW","GREEN")) | V34: =D34/(1+Assumptions!$C$2)-R34 | W34: =S34-V34 | X34: =E34-G34-E34*Assumptions!$C$3-E34*Assumptions!$C$4*Assumptions!$C$5-MIN(Assumptions!$C$9,Assumptions!$C$10*E34) | Y34: 40 | Z34: =IF(Y34="","",E34/Y34-1)
A35: 34 | B35: حسيه فرق خمير | D35: 27 | E35: 32.4 | F35: =E35/D35-1 | G35: =E35*Assumptions!$C$2/(1+Assumptions!$C$2) | H35: =E35*Assumptions!$C$3 | I35: =E35*Assumptions!$C$4*Assumptions!$C$5 | J35: =IF(E35<30,Assumptions!$C$11,LOOKUP(E35,Assumptions!$A$17:$A$21,Assumptions!$B$17:$B$21)) | K35: =H35+I35+J35 | L35: =E35-G35-K35 | M35: =L35/D35 | N35: =L35/E35 | O35: =L35/(D35/(1+Assumptions!$C$2)) | P35: =L35-Assumptions!$C$6 | Q35: =L35 | R35: =Assumptions!$C$7*D35/(1+Assumptions!$C$2)+Assumptions!$C$8 | S35: =L35-R35 | T35: =S35/(E35/(1+Assumptions!$C$2)) | U35: =IF(T35<0.15,"RED",IF(T35<0.3,"YELLOW","GREEN")) | V35: =D35/(1+Assumptions!$C$2)-R35 | W35: =S35-V35 | X35: =E35-G35-E35*Assumptions!$C$3-E35*Assumptions!$C$4*Assumptions!$C$5-MIN(Assumptions!$C$9,Assumptions!$C$10*E35) | Y35: 20 | Z35: =IF(Y35="","",E35/Y35-1)
A36: 35 | B36: حسيه سمك | D36: 48 | E36: 57.6 | F36: =E36/D36-1 | G36: =E36*Assumptions!$C$2/(1+Assumptions!$C$2) | H36: =E36*Assumptions!$C$3 | I36: =E36*Assumptions!$C$4*Assumptions!$C$5 | J36: =IF(E36<30,Assumptions!$C$11,LOOKUP(E36,Assumptions!$A$17:$A$21,Assumptions!$B$17:$B$21)) | K36: =H36+I36+J36 | L36: =E36-G36-K36 | M36: =L36/D36 | N36: =L36/E36 | O36: =L36/(D36/(1+Assumptions!$C$2)) | P36: =L36-Assumptions!$C$6 | Q36: =L36 | R36: =Assumptions!$C$7*D36/(1+Assumptions!$C$2)+Assumptions!$C$8 | S36: =L36-R36 | T36: =S36/(E36/(1+Assumptions!$C$2)) | U36: =IF(T36<0.15,"RED",IF(T36<0.3,"YELLOW","GREEN")) | V36: =D36/(1+Assumptions!$C$2)-R36 | W36: =S36-V36 | X36: =E36-G36-E36*Assumptions!$C$3-E36*Assumptions!$C$4*Assumptions!$C$5-MIN(Assumptions!$C$9,Assumptions!$C$10*E36) | Y36: 35 | Z36: =IF(Y36="","",E36/Y36-1)
A37: 36 | B37: حسيه لحوح لحم | D37: 48 | E37: 57.6 | F37: =E37/D37-1 | G37: =E37*Assumptions!$C$2/(1+Assumptions!$C$2) | H37: =E37*Assumptions!$C$3 | I37: =E37*Assumptions!$C$4*Assumptions!$C$5 | J37: =IF(E37<30,Assumptions!$C$11,LOOKUP(E37,Assumptions!$A$17:$A$21,Assumptions!$B$17:$B$21)) | K37: =H37+I37+J37 | L37: =E37-G37-K37 | M37: =L37/D37 | N37: =L37/E37 | O37: =L37/(D37/(1+Assumptions!$C$2)) | P37: =L37-Assumptions!$C$6 | Q37: =L37 | R37: =Assumptions!$C$7*D37/(1+Assumptions!$C$2)+Assumptions!$C$8 | S37: =L37-R37 | T37: =S37/(E37/(1+Assumptions!$C$2)) | U37: =IF(T37<0.15,"RED",IF(T37<0.3,"YELLOW","GREEN")) | V37: =D37/(1+Assumptions!$C$2)-R37 | W37: =S37-V37 | X37: =E37-G37-E37*Assumptions!$C$3-E37*Assumptions!$C$4*Assumptions!$C$5-MIN(Assumptions!$C$9,Assumptions!$C$10*E37) | Y37: 35 | Z37: =IF(Y37="","",E37/Y37-1)
A38: 37 | B38: حسيه دقيق لحم | D38: 48 | E38: 57.6 | F38: =E38/D38-1 | G38: =E38*Assumptions!$C$2/(1+Assumptions!$C$2) | H38: =E38*Assumptions!$C$3 | I38: =E38*Assumptions!$C$4*Assumptions!$C$5 | J38: =IF(E38<30,Assumptions!$C$11,LOOKUP(E38,Assumptions!$A$17:$A$21,Assumptions!$B$17:$B$21)) | K38: =H38+I38+J38 | L38: =E38-G38-K38 | M38: =L38/D38 | N38: =L38/E38 | O38: =L38/(D38/(1+Assumptions!$C$2)) | P38: =L38-Assumptions!$C$6 | Q38: =L38 | R38: =Assumptions!$C$7*D38/(1+Assumptions!$C$2)+Assumptions!$C$8 | S38: =L38-R38 | T38: =S38/(E38/(1+Assumptions!$C$2)) | U38: =IF(T38<0.15,"RED",IF(T38<0.3,"YELLOW","GREEN")) | V38: =D38/(1+Assumptions!$C$2)-R38 | W38: =S38-V38 | X38: =E38-G38-E38*Assumptions!$C$3-E38*Assumptions!$C$4*Assumptions!$C$5-MIN(Assumptions!$C$9,Assumptions!$C$10*E38) | Y38: 35 | Z38: =IF(Y38="","",E38/Y38-1)
A39: 38 | B39: حسيه بيتنا (عزبه) | D39: 62 | E39: 74.4 | F39: =E39/D39-1 | G39: =E39*Assumptions!$C$2/(1+Assumptions!$C$2) | H39: =E39*Assumptions!$C$3 | I39: =E39*Assumptions!$C$4*Assumptions!$C$5 | J39: =IF(E39<30,Assumptions!$C$11,LOOKUP(E39,Assumptions!$A$17:$A$21,Assumptions!$B$17:$B$21)) | K39: =H39+I39+J39 | L39: =E39-G39-K39 | M39: =L39/D39 | N39: =L39/E39 | O39: =L39/(D39/(1+Assumptions!$C$2)) | P39: =L39-Assumptions!$C$6 | Q39: =L39 | R39: =Assumptions!$C$7*D39/(1+Assumptions!$C$2)+Assumptions!$C$8 | S39: =L39-R39 | T39: =S39/(E39/(1+Assumptions!$C$2)) | U39: =IF(T39<0.15,"RED",IF(T39<0.3,"YELLOW","GREEN")) | V39: =D39/(1+Assumptions!$C$2)-R39 | W39: =S39-V39 | X39: =E39-G39-E39*Assumptions!$C$3-E39*Assumptions!$C$4*Assumptions!$C$5-MIN(Assumptions!$C$9,Assumptions!$C$10*E39) | Y39: 45 | Z39: =IF(Y39="","",E39/Y39-1)
... A43: 42 | B43: سلطه شرائح | D43: 10 | E43: 12 | F43: =E43/D43-1 | G43: =E43*Assumptions!$C$2/(1+Assumptions!$C$2) | H43: =E43*Assumptions!$C$3 | I43: =E43*Assumptions!$C$4*Assumptions!$C$5 | J43: =IF(E43<30,Assumptions!$C$11,LOOKUP(E43,Assumptions!$A$17:$A$21,Assumptions!$B$17:$B$21)) | K43: =H43+I43+J43 | L43: =E43-G43-K43 | M43: =L43/D43 | N43: =L43/E43 | O43: =L43/(D43/(1+Assumptions!$C$2)) | P43: =L43-Assumptions!$C$6 | Q43: =L43 | R43: =Assumptions!$C$7*D43/(1+Assumptions!$C$2)+Assumptions!$C$8 | S43: =L43-R43 | T43: =S43/(E43/(1+Assumptions!$C$2)) | U43: =IF(T43<0.15,"RED",IF(T43<0.3,"YELLOW","GREEN")) | V43: =D43/(1+Assumptions!$C$2)-R43 | W43: =S43-V43 | X43: =E43-G43-E43*Assumptions!$C$3-E43*Assumptions!$C$4*Assumptions!$C$5-MIN(Assumptions!$C$9,Assumptions!$C$10*E43) | Y43: 8 | Z43: =IF(Y43="","",E43/Y43-1)
...

Sheet Analysis_Tables
A2: تقييم عرض هنقرستيشن لمطعم «أكلات بيتنا» — نموذج قرار مالي
A4: الخلاصة في 8 أسطر
A6: 0) تفريق الحقائق عن الحسابات عن الافتراضات
A7: # | B7: الافتراض | C7: ملاحظة
A8: C1 | B8: أسعار المنيو والإكسل **شاملة** ضريبة القيمة المضافة 15% | C8: نظاماً أسعار المستهلك تُعرض شاملة الضريبة؛ لكن المستندات لم تذكر ذلك
A9: C2 | B9: نسبتا 21% و2.5% تُحسبان على **إجمالي الطلب شامل الضريبة** | C9: العقد: «من إجمالي قيمة الطلبات» + شرائح السلة شاملة الضريبة. **غير محسوم** → أعرض متغيراً بديلاً (ب)
A10: C3 | B10: ضريبة القيمة المضافة على فواتير المنصة قابلة للاسترداد (المطعم مسجل: رقم ضريبي موجود بالعقد) | C10: إن لم تكن قابلة للاسترداد ترتفع التكلفة ×1.15
A11: C4 | B11: جدول 7/8/9/11/13 ريال = مبلغ **يتحمله المطعم** عن كل طلب توصيل (صافٍ، بدون ضريبة إضافية) | C11: تفسير؛ النص لا يقول صراحة «يخصم من المطعم»
A12: C5 | B12: سلة أقل من 30 ريال: 7 ريال (أقل شريحة) | C12: العقد لا يعرّف شريحة أقل من 30 — فراغ تعاقدي
A13: C6 | B13: 100% من الطلبات مدفوعة إلكترونياً (تُطبق 2.5%) | C13: متحفظ؛ العقد يسميها «عمولة الدفع الإلكتروني»
A14: C7 | B14: عمود D في الإكسل = سعر المطعم الحالي المباشر، وعمود F = سعر هنقرستيشن (D×1.2) | C14: يتفق مع قولك إنك ترفع ~20%؛ لكن D ≠ المنيو المطبوع (قسم 13)
A15: C8 | B15: تكلفة الطعام = **32%** من سعر البيع المباشر بدون ضريبة + **2 ريال** تغليف/طلب | C15: **لم تُعطَ تكلفة** — أرقام مؤقتة يجب استبدالها بتكلفة الوصفات
A16: C9 | B16: الاستلام: العميل خصم 20%، المطعم يتحمل min(2.5 ريال، قيمة الخصم) والباقي على المنصة، والعمولة 21% على السعر الكامل | C16: نص العقد متناقض (قسم 13)
A17: C10 | B17: الاشتراك 200 ريال/شهر لمدة 4 أشهر (أكتوبر–يناير) والطابعة 500 ريال موزعة على 12 شهراً | C17: العقد يذكر مبلغ 200 وتاريخي بداية/نهاية فقط
A18: C11 | B18: رسوم توصيل يدفعها العميل (إن وُجدت) لا تعود للمطعم | C18: غير مذكورة في العقد
A19: C12 | B19: حدود التصنيف: 🔴 CM<15% · 🟡 15–30% · 🟢 ≥30% (من سعر HS بدون ضريبة) | C19: **تعريفي أنا** وليست من المستندات: 15% ≈ الحد الأدنى لتغطية هدر/استرجاع/عمالة تحضير؛ 30% ≈ نصف هامش البيع المباشر تقريباً
A21: 1) الشروط التجارية المستخرجة من العقد
A22: البند | B22: القيمة/النص | C22: الموضع
A23: عمولة توصيل هنقرستيشن | B23: **21.00%** من «إجمالي قيمة الطلبات»؛ تستمر طوال مدة العقد | C23: ص4 — خامساً-أ جدول «رسوم الخدمة الشهرية»
A24: عمولة الدفع الإلكتروني | B24: **2.50%** (نفس الأساس؛ لا يوضح العقد هل تنطبق على كل طلب) | C24: ص4 — خامساً-أ
A25: عمولة الاستلام من المتجر (Pickup) | B25: **21.00%** (مثل التوصيل تماماً) | C25: ص4 — خامساً-أ
A26: الاشتراك الشهري | B26: **200.00 ريال** — بداية 01/10/2026، نهاية 01/02/2027 (غير واضح: 200 شهرياً لـ4 أشهر أم 200 إجمالاً) | C26: ص4 — خامساً-ب
A27: رسوم الطابعة (دفعة واحدة) | B27: **500.00 ريال** طابعة V2s، بدون خصم، بداية 30/09/2026 | C27: ص4 — خامساً-ب
A28: رسوم تسجيل | B28: غير مذكورة | C28: —
A29: مساهمة المطعم في الخصومات | B29: الاستلام فقط: حد أقصى **2.5 ريال/طلب** (وإن كان الخصم أقل من 2.5 يتحمل المطعم كامله) إضافة للعمولة 21%؛ لا توجد خصومات توصيل/حملات منصوص عليها | C29: ص5 — خامساً-جـ (Pick up - Advanced Package)
A30: مساهمة هنقرستيشن في الخصومات | B30: خصم الاستلام «يبدأ من 20%» ويُموَّل الباقي من الطرف الأول؛ له تغيير النسبة وتحديد سقف عدد الطلبات وسقف الخصم للطلب | C30: ص5 — نفس البند
A31: مساهمة المطعم في تخفيض رسوم التوصيل (حسب السلة شاملة الضريبة) | B31: 30–39.99: **7** · 40–49.99: **8** · 50–59.99: **9** · 60–79.99: **11** · +80: **13** ريال؛ إلزامية طوال العقد؛ معايير التخفيض (مسافة، قيمة السلة…) «بإرادة الطرف الأول المنفردة». **لا توجد شريحة لأقل من 30** | C31: ص5–ص6 — (د) رسوم التوصيل المخفضة + اللقطة المرفقة (مطابقة للعقد)
A32: إضافة HPlus | B32: **+4 ريال/طلب** على المطعم لطلبات عملاء HPlus فقط (لا يدفع العميل رسوم توصيل) | C32: ص6 — (د)
A33: ضريبة القيمة المضافة | B33: ذُكرت **فقط** في: «نطاق السلة بالقيمة الإجمالية شاملة الضريبة». لا نص عن ضريبة على العمولات أو أساس احتسابها. الرقم الضريبي للمطعم في ص1 | C33: ص6 / ص1
... A40: بنود أخرى مؤثرة | B40: منع التنازل عن العقد دون موافقة؛ نزاع: ودي 30 يوماً ثم محاكم الرياض؛ المطعم مسؤول عن تحديث بيانات التواصل وأي إشعار على آخر وسيلة نافذ | C40: ص3 — رابعاً
A42: 2) تحليل كل صنف (56 صنفاً في الإكسل)
A43: # | B43: الصنف | C43: سعر المطعم | D43: سعر HS | E43: الزيادة | F43: ضريبة مضمنة | G43: عمولة 21% | H43: دفع 2.5% | I43: توصيل | J43: إجمالي خصومات المنصة | K43: الصافي قبل التكلفة | L43: % من سعر المطعم | M43: % من سعر HS | N43: أقصى تكلفة طعام+تغليف | O43: صافي لو HPlus
A44: 1 | B44: نفر حنيد بيتنا | C44: 105 | D44: 126 | E44: 20% | F44: 16.43 | G44: 26.46 | H44: 3.15 | I44: 13 | J44: 42.61 | K44: 66.96 | L44: 64% | M44: 53% | N44: 66.96 | O44: 62.96
A45: 2 | B45: حنيذ جيزاني | C45: 100 | D45: 120 | E45: 20% | F45: 15.65 | G45: 25.2 | H45: 3 | I45: 13 | J45: 41.2 | K45: 63.15 | L45: 63% | M45: 53% | N45: 63.15 | O45: 59.15
A46: 3 | B46: كبسة لحم | C46: 98 | D46: 117.6 | E46: 20% | F46: 15.34 | G46: 24.7 | H46: 2.94 | I46: 13 | J46: 40.64 | K46: 61.62 | L46: 63% | M46: 52% | N46: 61.62 | O46: 57.62
A47: 4 | B47: برمة لحم مع الرز | C47: 48 | D47: 57.6 | E47: 20% | F47: 7.51 | G47: 12.1 | H47: 1.44 | I47: 9 | J47: 22.54 | K47: 27.55 | L47: 57% | M47: 48% | N47: 27.55 | O47: 23.55
A48: 5 | B48: مغش لحم | C48: 59 | D48: 70.8 | E48: 20% | F48: 9.23 | G48: 14.87 | H48: 1.77 | I48: 11 | J48: 27.64 | K48: 33.93 | L48: 58% | M48: 48% | N48: 33.93 | O48: 29.93
A49: 6 | B49: ربع شواية مع الرز | C49: 19 | D49: 22.8 | E49: 20% | F49: 2.97 | G49: 4.79 | H49: 0.57 | I49: 7 | J49: 12.36 | K49: 7.47 | L49: 39% | M49: 33% | N49: 7.47 | O49: 3.47
A50: 7 | B50: نص شواية مع الرز | C50: 27 | D50: 32.4 | E50: 20% | F50: 4.23 | G50: 6.8 | H50: 0.81 | I50: 7 | J50: 14.61 | K50: 13.56 | L50: 50% | M50: 42% | N50: 13.56 | O50: 9.56
A51: 8 | B51: حبه شوايه مع الرز | C51: 55 | D51: 66 | E51: 20% | F51: 8.61 | G51: 13.86 | H51: 1.65 | I51: 11 | J51: 26.51 | K51: 30.88 | L51: 56% | M51: 47% | N51: 30.88 | O51: 26.88
...
